Workbook
Name Slicer_Category: #N/A
Name Slicer_Category1: #N/A
Name Slicer_Products: #N/A
Name Slicer_Region: #N/A
Name Slicer_Status: #N/A

Sheet Darta Quality Report
A1: DATA QUALITY ASSESSMENT AND CLEARNING REPORT
A3: Project Overview This report documents all data quality issues identified in the e-commerce dataset and the cleaning decisions made to prepare the data for analysis. Original Dataset 515 records (including duplicates) Final Clean Dataset 501 records after cleaning 12 Columns after cleaning Data Quality Issues Found 7 major categories of issues (detailed below)
A20: 1) Issue Category DUPLICATE RECORDS Description Complete duplicate orders found across all columns Count Found 15 duplicate records Resolution: Removed duplicates using "Remove Duplicates" function, keeping first occurrence Impact: Reduced dataset from 515 to ~500 records. Ensures accurate order counts and revenue totals. | J20: 2) Issue Category MISSING CUSTOMER IDs Description Customer ID field contained NULL values and empty strings Count Found 30 records Resolution Assigned placeholder value "CUST9999" (Unknown Customer) to all missing IDs Impact Preserved order-level data for product and revenue analysis. Can track "Unknown Customer" segment separately. Recommendation: Implement mandatory customer capture.
A38: 3) Issue Category INCONSISTENT PRODUCT NAMES Description Mixed case (laptop, LAPTOP, Laptop), extra whitespace, typos with Cyrillic characters Count Found ~50 records with formatting issues, ~15 with typos Resolution Applied TRIM() to remove spaces, PROPER() to standardize case, Find & Replace to fix typos (Laптop → Laptop) Impact Ensures accurate product grouping in analysis. All products now consistently formatted. | J38: 4) Issue Category INCONSISTENT CATEGORIES & MISSING VALUES Description Mixed case (electronics, Electronics), ~25 NULL values Count Found ~40 formatting issues, ~25 missing values Resolution Standardized to Title Case using PROPER(TRIM()). Filled missing values based on product mapping (e.g., Laptop → Electronics, Mouse → Accessories) Impact Enables accurate category-level revenue analysis and reporting.
A59: 5) Issue Category INCONSISTENT DATE FORMATS Description Multiple formats: YYYY-MM-DD, DD/MM/YYYY, MM-DD-YYYY Invalid dates: 2024-13-45 (impossible month) Count Found ~10 NULL dates, ~15 format inconsistencies, ~10 invalid dates Resolution Used DATEVALUE() function to convert all formats to standard dates. Deleted/replaced invalid dates. Formatted entire column as Short Date. Impact Enables time-series analysis and monthly trend reporting. | J59: 6) Issue Category INVALID QUANTITIES AND PRICES Description Negative quantities (-1 to -4), zero quantities Negative unit prices, zero unit prices Count Found Quantities: ~10 negative, ~15 zero Prices: ~10 negative, ~15 zero Resolution QUANTITIES: Replaced with median value (3 units) PRICES: Replaced with product-specific average prices (Laptop=$900, Mouse=$26, etc.) Impact Preserved transaction records while correcting obvious data entry errors. Revenue calculations now accurate. Rationale Chose median for quantities (similar across products). Chose product-specific averages for prices (vary by product). Deletion would have lost valuable order metadata.
A80: 7) Issue Category OUTLIER VALUES - QUANTITY 999 Description Orders with exactly 999 units (possible bulk orders or data entry placeholder) Count Found ~10 records Resolution Categiruzed as "Bulk Orders" for separate analysis CATEGORIZED AS "BULK ORDERS" Created separate order type category for analysis flexibility. Enables filtering bulk vs. regular orders in reporting. Impact Rather than delete or modify, created order type segmentation ot preserve data integrity while allowing filtered analysis of regular vs bulk purchasing patterns.
J85: 8) Issue Category INCORRECT REVENUE CALCULATIONS Description Revenue values did not match Quantity × Unit Price formula Count Found ~75 records (~15% of dataset) Resolution Recalculated all revenue values using formula: Revenue = Quantity × Unit Price Verified 100% accuracy using error-checking formula Impact Corrected total revenue by $1,910,051.04 . Ensures financial reporting accuracy.
A102: 9) Issue Category INVALID EMAIL FORMATS Description Missing @ symbols, incomplete addresses, empty strings Count Found ~25 records with email format issues Resolution LEFT AS-IS with documentation (Email validation not critical for sales analysis) Impact Does not impact revenue or product analysis. Recommendation: Implement email validation at data entry.

Sheet Key Insights
E2: Key Insights
A5: FINDING #1: Product Performance Top Revenue-Generating Products: 1. Monitor - $431,230.84 (28.0%) - 63 orders 2. Laptop - $279,686.77 (18.2%) - 71 orders 3. Headphones - $206,214.00 (13.4%) - 59 orders INSIGHT: Monitors surprisingly lead revenue generation at 28%, outperforming laptops despite fewer orders (63 vs 71). This indicates higher average selling prices for monitors. The top 3 products account for 59.6% of total revenue, showing significant concentration in premium electronics. Monitors generate $6,844 per order vs laptops at $3,939, nearly 2x higher transaction value. RECOMMENDATION: Capitalize on monitor dominance: Create monitor bundles with keyboards and mice to increase accessories attachment. Target: Increase monitor orders from 63 to 80 (27% growth) = $108,000 additional revenue. Develop premium monitor line ($500+) to maintain high AOV. Cross-sell monitors to laptop buyers - currently only 89% overlap rate. | I5: FINDING #2: Category Distribution Revenue by Category: • Electronics: $909,292.59 (59.1%) - 200 orders - AOV: $4,546 • Accessories: $398,341.93 (25.9%) - 185 orders - AOV: $2,153 • Audio: $206,214.00 (13.4%) - 63 orders - AOV: $3,273 • Other: $25,683.49 (1.7%) - 52 orders - AOV: $494 INSIGHT: Electronics dominate with 59.1% revenue share but represent only 40% of orders, demonstrating premium pricing power. Accessories drive volume (37% of orders) but at lower margins. The 2.1x AOV difference between Electronics and Accessories shows clear customer segmentation. The 'Other' category with 52 orders but minimal revenue suggests data quality issues or clearance items. RECOMMENDATION: Strategy 1: Increase accessories revenue through bundling - implement 'Complete Your Setup' recommendations at checkout. Target: Raise accessories AOV from $2,153 to $2,500 (+16%) = $64,000 additional revenue. Strategy 2: Protect electronics margins through value-added services (installation, extended warranty, tech support). Strategy 3: Investigate 'Other' category - either reclassify products properly or discontinue low-performers. | Q5: FINDING #3: Regional Performance Disparity Regional Revenue Analysis: • East: $494,066.81 (32.1%) - 92 orders - AOV: $5,370 • South: $340,694.11 (22.1%) - 89 orders - AOV: $3,828 • North: $294,413.33 (19.1%) - 98 orders - AOV: $3,004 • West: $294,096.67 (19.1%) - 100 orders - AOV: $2,941 • Central: $105,769.69 (6.9%) - 101 orders - AOV: $1,047 INSIGHT: CRITICAL ISSUE: Central region severely underperforms with AOV of only $1,047 - 5.1x lower than East region ($5,370). Despite having the most orders (101), Central generates only 6.9% of revenue. East region's AOV is 83% higher than company average, indicating either premium customer base or superior sales execution. The $388,297 gap between best and worst regions represents 25% of total revenue. RECOMMENDATION: URGENT ACTION REQUIRED for Central region: Immediate investigation into why AOV is $1,047 vs $3,201 company average. Hypotheses: (1) pricing errors, (2) only selling accessories not electronics, (3) different customer segment, (4) operational issues. Action Plan: Week 1-2: Audit Central orders - product mix analysis, pricing verification, customer interviews. Month 1: Pilot East region tactics in Central (same marketing, promotions, product selection). Target: Raise Central AOV to $2,000 = $96,000 additional revenue. East region: Document and replicate success factors company-wide.
A27: FINDING #4: Order Fulfillment Crisis Order Status Breakdown: • Completed: 110 orders (22.0%) - $519,262.72 • Pending: 143 orders (28.6%) - $305,283.40 • Cancelled: 117 orders (23.4%) - $189,145.05 • Refunded: 122 orders (24.4%) - $523,613.27 INSIGHT: Only 22% order completion rate is catastrophically low (industry standard: 85-90%). 47.8% of orders are cancelled or refunded, representing $712,758 in lost revenue (46% of total revenue). 143 pending orders worth $305,283 suggest fulfillment backlog or checkout abandonment. This completion rate indicates severe operational problems that threaten business viability. If completion rate were industry-standard 85%, revenue would be $5.9M instead of $1.5M. RECOMMENDATION: This is the #1 priority issue. Wait for new customer acquisition until fulfillment is fixed. Emergency analysis: Why are 23.4% cancelled? Why 24.4% refunded? Review refund reasons, customer complaints, product quality issues. Pending Order Recovery, 143 pending orders = $305,283 at risk. Implement 48-hour follow-up for all pending. Target: Convert 50% to completed = $152,000 recovered. Root Cause Analysis, Investigate - inventory issues, shipping delays, product descriptions misleading, pricing errors, payment processing. Increase completion rate from 22% to 60% minimum. This could add $2.3M annual revenue. | I27: FINDING #5: Bulk Order Opportunity Order Type Analysis: • Bulk Orders (100+ units): $987,539 (64.1%) - 17 orders • Regular Orders: $551,993 (35.9%) - 483 orders INSIGHT: Just 17 bulk orders (3.4% of total) generate 64.1% of revenue, averaging $58,091 per bulk order vs $1,143 for regular orders (51x difference). This indicates a B2B or enterprise sales channel that's highly profitable but inconsistent. Business is heavily dependent on large deals - loss of even 2-3 bulk customers would devastate revenue. RECOMMENDATION: Develop formal B2B sales strategy: Strategy 1: Identify and nurture bulk buyers - assign dedicated account managers to the 17 bulk order customers. Goal: Retain 100% and increase frequency. Strategy 2: Proactive B2B outreach to corporations, schools, government entities. Target: Add 10 new bulk order customers = $580,000 revenue. Strategy 3: Create volume pricing tiers (50+, 100+, 500+ units) with clear incentives. Strategy 4: Develop bulk order management system - quotes, contracts, net-30 terms. Risk Mitigation: Diversify revenue - can't rely on 17 customers for 64% of revenue.

Sheet Dashboard
A1: E-Commerce Sales Dashboard
A2: January 2023 - December 2024
B3: TOTAL REVENUE | F3: TOTAL ORDERS | J3: AVERAGE ORDER VALUE
B4: =Analysis!B27 -> 1539532 | F4: =Analysis!B26 -> 515 | J4: =Analysis!B28 -> 2989.3825
B7: UNIQUE CUSTOMERS
B8: =Analysis!B29 -> 225

Sheet Analysis
A2: Revenue by Products | I2: Revenue for Category
A3: Row Labels | B3: Sum of Revenue | I3: Row Labels | J3: Sum of Revenue
A4: Monitor | B4: 431230.84 | I4: Electronics | J4: 909292.59
A5: Laptop | B5: 279686.77 | I5: Accessories | J5: 398341.93
A6: Headphones | B6: 206214 | I6: Audio | J6: 206214
A7: Webcam | B7: 199479.87 | I7: Other | J7: 25683.49
A8: Laptop Stand | B8: 177135.28 | I8: (blank)
A9: Keyboard | B9: 115465.53 | I9: Grand Total | J9: 1539532
A10: Mouse | B10: 104636.23
A11: Usb Cable | B11: 25683.49
A12: (blank)
A13: Grand Total | B13: 1539532 | I13: Revenue by Region
I14: Row Labels | J14: Sum of Revenue | L14: Revenue by Status
I15: East | J15: 494066.81 | L15: Row Labels | M15: Sum of Revenue
A16: Orders By Month | I16: South | J16: 340694.11 | L16: Refunded | M16: 523613.27
A17: Row Labels | B17: Sum of Revenue | I17: North | J17: 294413.33 | L17: Completed | M17: 519262.72
A18: <1/8/2023 | B18: 25504.326 | I18: West | J18: 294096.67 | L18: Pending | M18: 305283.4
A19: 2023 | B19: 459821.59 | I19: Central | J19: 105769.69 | L19: Cancelled | M19: 189145.05
A20: 2024 | B20: 1054206.1 | I20: (blank) | J20: 10491.4 | L20: Grand Total | M20: 1537304.4
A21: Grand Total | B21: 1539532 | I21: Grand Total | J21: 1539532
I23: Top Customer Analysis
I24: Row Labels | J24: Sum of Revenue
A25: Analysis | I25: CUST0174 | J25: 304255.72
A26: Total Orders | B26: =COUNTA('Old Data'!A:A)-1 -> 515 | I26: CUST0138 | J26: 153767.64
A27: Total Revenue | B27: =SUM('Clean Data'!I:I) -> 1539532 | I27: CUST0069 | J27: 86912.52
A28: Average Order Value | B28: =B27/B26 -> 2989.3825 | I28: CUST0161 | J28: 82367.55
A29: Unique Customers | B29: 225 | I29: CUST0003 | J29: 81487.91
I30: CUST0267 | J30: 58801.32
I31: CUST0019 | J31: 53776.17
I32: CUST0111 | J32: 52179.19
I33: CUST0122 | J33: 51783.84
I34: CUST0020 | J34: 50482.5
I35: Grand Total | J35: 975814.36

Sheet Clean Data
A1: Order ID | B1: Customer ID | C1: Order Date | D1: Products | E1: Category | F1: Quantity | G1: Order Type | H1: Unit Price | I1: Revenue | J1: Status | K1: Region | L1: Email | N1: Unkown Customer Revenue | O1: Percentage of Unknown Orders
A2: ORD00305 | B2: CUST0022 | C2: 45376 | D2: Laptop Stand | E2: Accessories | F2: 2 | G2: =IF(F2> 100, "Bulk Order", "Regular Order") -> Regular Order | H2: 47.08 | I2: 94.16 | J2: Pending | K2: East | L2: customer0022@example.com | N2: =SUMIF(B:B, "CUST9999", I:I) -> 37145 | O2: =COUNTIF(B:B,"CUST9999")/COUNTA(B:B) -> 0.05988024
A3: ORD00500 | B3: CUST0097 | C3: 45455 | D3: Headphones | E3: Audio | F3: 2 | G3: =IF(F3> 100, "Bulk Order", "Regular Order") -> Regular Order | H3: 164.86 | I3: 329.72 | J3: Pending | K3: North | L3: customer0097@example.com
A4: ORD00442 | B4: CUST0255 | C4: 45063 | D4: Laptop | E4: Electronics | F4: 9 | G4: =IF(F4> 100, "Bulk Order", "Regular Order") -> Regular Order | H4: 822.22 | I4: =F4*H4 -> 7399.98 | J4: Refunded | K4: East | L4: customer0255@example.com
A5: ORD00154 | B5: CUST0182 | C5: 45352 | D5: Headphones | E5: Audio | F5: 6 | G5: =IF(F5> 100, "Bulk Order", "Regular Order") -> Regular Order | H5: 141.63 | I5: 4554.55 | J5: Completed | K5: Central | L5: customer0182@example.com
A6: ORD00074 | B6: CUST0164 | C6: 45391 | D6: Keyboard | E6: Accessories | F6: 2 | G6: =IF(F6> 100, "Bulk Order", "Regular Order") -> Regular Order | H6: 79.34 | I6: 423.72 | J6: Completed | K6: North | L6: customer0164@example.com
A7: ORD00132 | B7: CUST0128 | C7: 45208 | D7: Laptop | E7: Electronics | F7: 5 | G7: =IF(F7> 100, "Bulk Order", "Regular Order") -> Regular Order | H7: 910.91 | I7: =F7*H7 -> 4554.55 | J7: Refunded | K7: North | L7: customer0128@example.com
A8: ORD00205 | B8: CUST0254 | C8: 45114 | D8: Laptop | E8: Electronics | F8: 7 | G8: =IF(F8> 100, "Bulk Order", "Regular Order") -> Regular Order | H8: 843.12 | I8: 84.24 | J8: Completed | K8: Central | L8: customer0254@example.com
A9: ORD00010 | B9: CUST9999 | C9: 45134 | D9: Keyboard | E9: Accessories | F9: 9 | G9: =IF(F9> 100, "Bulk Order", "Regular Order") -> Regular Order | H9: =IF(H2<=0, AVERAGEIF($D:$D,D2,$H:$H),H2) -> 47.08 | I9: =F9*H9 -> 423.72 | J9: Pending | K9: West
A10: ORD00326 | B10: CUST0125 | C10: 45642 | D10: Headphones | E10: Audio | F10: 3 | G10: =IF(F10> 100, "Bulk Order", "Regular Order") -> Regular Order | H10: 910.91 | I10: =F10*H10 -> 2732.73 | J10: Pending | K10: West | L10: customer0125@example.com
A11: ORD00248 | B11: CUST0078 | C11: 45546 | D11: Laptop | E11: Electronics | F11: 1 | G11: =IF(F11> 100, "Bulk Order", "Regular Order") -> Regular Order | H11: 84.24 | I11: =F11*H11 -> 84.24 | J11: Refunded | K11: West | L11: customer0078@example.com
A12: ORD00466 | B12: CUST0087 | C12: 45107 | D12: Laptop | E12: Electronics | F12: 9 | G12: =IF(F12> 100, "Bulk Order", "Regular Order") -> Regular Order | H12: 53.41 | I12: =F12*H12 -> 480.69 | J12: Refunded | K12: South | L12: customer0087@example.com
A13: ORD00354 | B13: CUST0061 | C13: 45295 | D13: Laptop | E13: Electronics | F13: 1 | G13: =IF(F13> 100, "Bulk Order", "Regular Order") -> Regular Order | H13: 135.17 | I13: =F13*H13 -> 135.17 | J13: Pending | K13: West | L13: customer0061@example.com
A14: ORD00290 | B14: CUST0112 | C14: 45218 | D14: Webcam | E14: Electronics | F14: 5 | G14: =IF(F14> 100, "Bulk Order", "Regular Order") -> Regular Order | H14: =IF(H7<=0, AVERAGEIF($D:$D,D7,$H:$H),H7) -> 910.91 | I14: =F14*H14 -> 4554.55 | J14: Completed | K14: Central | L14: customer0112@example.com
A15: ORD00085 | B15: CUST0086 | C15: 45215 | D15: Laptop | E15: Electronics | F15: 2 | G15: =IF(F15> 100, "Bulk Order", "Regular Order") -> Regular Order | H15: 25.9 | I15: =F15*H15 -> 51.8 | J15: Pending | K15: West | L15: customer0086@example.com
A16: ORD00011 | B16: CUST9999 | C16: 45430 | D16: Laptop Stand | E16: Accessories | F16: 6 | G16: =IF(F16> 100, "Bulk Order", "Regular Order") -> Regular Order | H16: 813.8 | I16: =F16*H16 -> 4882.8 | J16: Refunded | K16: East
A17: ORD00325 | B17: CUST0126 | C17: 45085 | D17: Keyboard | E17: Accessories | F17: 6 | G17: =IF(F17> 100, "Bulk Order", "Regular Order") -> Regular Order | H17: 49.33 | I17: =F17*H17 -> 295.98 | J17: Pending | L17: customer0126@example.com
A18: ORD00079 | B18: CUST0186 | C18: 45582 | D18: Laptop Stand | E18: Accessories | F18: 7 | G18: =IF(F18> 100, "Bulk Order", "Regular Order") -> Regular Order | H18: 26.1 | I18: =F18*H18 -> 182.7 | J18: Pending | K18: North | L18: customer0186@example.com
A19: ORD00031 | B19: CUST0001 | D19: Mouse | E19: Accessories | F19: 8 | G19: =IF(F19> 100, "Bulk Order", "Regular Order") -> Regular Order | H19: 46.74 | I19: =F19*H19 -> 373.92 | J19: Cancelled | K19: North | L19: customer0001@example.com
A20: ORD00185 | B20: CUST0174 | C20: 45078 | D20: Keyboard | E20: Accessories | F20: 8 | G20: =IF(F20> 100, "Bulk Order", "Regular Order") -> Regular Order | H20: 97.14 | I20: =F20*H20 -> 777.12 | J20: Cancelled | K20: West | L20: customer0174@example.com
A21: ORD00196 | B21: CUST0074 | C21: 45200 | D21: Mouse | E21: Accessories | F21: 8 | G21: =IF(F21> 100, "Bulk Order", "Regular Order") -> Regular Order | H21: 91.53 | I21: =F21*H21 -> 732.24 | J21: Cancelled | K21: South | L21: customer0074@example.com
A22: ORD00223 | B22: CUST0257 | C22: 45582 | D22: Headphones | E22: Audio | F22: 6 | G22: =IF(F22> 100, "Bulk Order", "Regular Order") -> Regular Order | H22: 49.86 | I22: =F22*H22 -> 299.16 | J22: Completed | K22: West | L22: customer0257@example.com
A23: ORD00210 | B23: CUST0045 | C23: 45328 | D23: Webcam | E23: Electronics | F23: 5 | G23: =IF(F23> 100, "Bulk Order", "Regular Order") -> Regular Order | H23: 986.85 | I23: =F23*H23 -> 4934.25 | J23: Refunded | K23: South | L23: customer0045@example.com
A24: ORD00282 | B24: CUST0242 | C24: 45528 | D24: Laptop Stand | E24: Accessories | F24: 3 | G24: =IF(F24> 100, "Bulk Order", "Regular Order") -> Regular Order | H24: 24.88 | I24: =F24*H24 -> 74.64 | J24: Cancelled | K24: North | L24: customer0242@example.com
A25: ORD00209 | B25: CUST0027 | C25: 45378 | D25: Laptop Stand | E25: Accessories | F25: 7 | G25: =IF(F25> 100, "Bulk Order", "Regular Order") -> Regular Order | H25: 93.08 | I25: =F25*H25 -> 651.56 | J25: Refunded | K25: Central | L25: customer0027@example.com
A26: ORD00125 | B26: CUST0065 | C26: 45521 | D26: Mouse | E26: Accessories | F26: 1 | G26: =IF(F26> 100, "Bulk Order", "Regular Order") -> Regular Order | H26: 151.24 | I26: =F26*H26 -> 151.24 | J26: Refunded | K26: South | L26: customer0065@example.com
A27: ORD00251 | B27: CUST0233 | D27: Keyboard | E27: Accessories | F27: 8 | G27: =IF(F27> 100, "Bulk Order", "Regular Order") -> Regular Order | H27: 52.42 | I27: =F27*H27 -> 419.36 | J27: Pending | K27: Central | L27: customer0233example.com
A28: ORD00077 | B28: CUST0288 | C28: 45214 | D28: Monitor | E28: Electronics | F28: 2 | G28: =IF(F28> 100, "Bulk Order", "Regular Order") -> Regular Order | H28: 46.145417 | I28: =F28*H28 -> 92.290833 | J28: Refunded | K28: North | L28: customer0288@example.com
A29: ORD00383 | B29: CUST0204 | C29: 45384 | D29: Webcam | E29: Electronics | F29: 8 | G29: =IF(F29> 100, "Bulk Order", "Regular Order") -> Regular Order | H29: 53.76 | I29: =F29*H29 -> 430.08 | J29: Cancelled | K29: South | L29: customer0204@example.com
A30: ORD00343 | B30: CUST0287 | C30: 45212 | D30: Monitor | E30: Electronics | F30: 8 | G30: =IF(F30> 100, "Bulk Order", "Regular Order") -> Regular Order | H30: 27.68 | I30: =F30*H30 -> 221.44 | J30: Completed | K30: South | L30: customer0287@example.com
A31: ORD00324 | B31: CUST0288 | C31: 45235 | D31: Keyboard | E31: Accessories | F31: 5 | G31: =IF(F31> 100, "Bulk Order", "Regular Order") -> Regular Order | H31: 72.15 | I31: =F31*H31 -> 360.75 | J31: Refunded | K31: North | L31: customer0288@example.com
A32: ORD00245 | B32: CUST0043 | C32: 45021 | D32: Mouse | E32: Accessories | F32: 1 | G32: =IF(F32> 100, "Bulk Order", "Regular Order") -> Regular Order | H32: 23.972407 | I32: =F32*H32 -> 23.972407 | J32: Pending | K32: Central | L32: customer0043example.com
A33: ORD00332 | B33: CUST0245 | C33: 45483 | D33: Laptop | E33: Electronics | F33: 8 | G33: =IF(F33> 100, "Bulk Order", "Regular Order") -> Regular Order | H33: 140.5 | I33: =F33*H33 -> 1124 | J33: Pending | K33: Central | L33: customer0245@example.com
A34: ORD00141 | B34: CUST0230 | C34: 45364 | D34: Mouse | E34: Accessories | F34: 7 | G34: =IF(F34> 100, "Bulk Order", "Regular Order") -> Regular Order | H34: 77.45 | I34: =F34*H34 -> 542.15 | J34: Refunded | K34: North | L34: customer0230@example.com
A35: ORD00073 | B35: CUST0116 | C35: 45629 | D35: Webcam | E35: Electronics | F35: 5 | G35: =IF(F35> 100, "Bulk Order", "Regular Order") -> Regular Order | I35: 267.05 | J35: Cancelled | K35: Central | L35: customer0116@example.com
A36: ORD00401 | B36: CUST0264 | D36: Laptop | E36: Electronics | F36: 3 | G36: =IF(F36> 100, "Bulk Order", "Regular Order") -> Regular Order | H36: =IF(H29<=0, AVERAGEIF($D:$D,D29,$H:$H),H29) -> 53.76 | I36: =F36*H36 -> 161.28 | J36: Pending | K36: North | L36: 0264@
A37: ORD00488 | B37: CUST0080 | C37: 45056 | D37: Monitor | E37: Electronics | F37: 2 | G37: =IF(F37> 100, "Bulk Order", "Regular Order") -> Regular Order | H37: 287.94 | I37: 187.8 | J37: Pending | K37: West | L37: customer0080@example.com
A38: ORD00226 | B38: CUST0024 | C38: 45437 | D38: Mouse | E38: Accessories | F38: 1 | G38: =IF(F38> 100, "Bulk Order", "Regular Order") -> Regular Order | H38: 25.5 | I38: 675.85 | J38: Pending | K38: East | L38: customer0024@example.com
A39: ORD00178 | B39: CUST0051 | C39: 45652 | D39: Usb Cable | E39: Other | F39: 1 | G39: =IF(F39> 100, "Bulk Order", "Regular Order") -> Regular Order | H39: 49.6 | I39: 767.65 | J39: Pending | K39: East | L39: customer0051@example.com
A40: ORD00404 | B40: CUST0250 | C40: 45243 | D40: Webcam | E40: Electronics | F40: 5 | G40: =IF(F40> 100, "Bulk Order", "Regular Order") -> Regular Order | H40: 85.01 | I40: 2417.04 | J40: Cancelled | K40: North | L40: customer0250@example.com
...

Sheet Old Data
A1: Order ID | B1: Customer ID | C1: Order Date | D1: Product | E1: Category | F1: Quantity | G1: Unit Price | H1: Revenue | I1: Status | J1: Region | K1: Email
A2: ORD00305 | B2: CUST0022 | C2: 2024-03-25 | D2: laptop stand | E2: Accessories | F2: 2 | G2: 47.08 | H2: 94.16 | I2: Pending | J2: East | K2: customer0022@example.com
A3: ORD00500 | B3: CUST0097 | C3: 2024-06-12 | D3: Headphones | E3: Audio | F3: 2 | G3: 164.86 | H3: 329.72 | I3: Pending | J3: North | K3: customer0097@example.com
A4: ORD00442 | B4: CUST0255 | C4: 2023-05-17 | D4: Laptop | F4: 9 | G4: 822.22 | H4: 7465.66 | I4: Refunded | J4: East | K4: customer0255@example.com
A5: ORD00154 | B5: CUST0182 | C5: 2024-03-01 | D5: Headphones | E5: Audio | F5: 6 | G5: 141.63 | H5: 849.78 | I5: Completed | J5: central | K5: customer0182@example.com
A6: ORD00074 | B6: CUST0164 | C6: 2024-04-09 | D6: Keyboard | E6: Accessories | F6: 2 | G6: 79.34 | H6: 158.68 | I6: Completed | J6: North | K6: customer0164@example.com
A7: ORD00132 | B7: CUST0128 | C7: 2023-10-09 | D7: Laptop | E7: Electronics | F7: 0 | G7: 910.91 | H7: 0 | I7: Refunded | J7: North | K7: customer0128@example.com
A8: ORD00205 | B8: CUST0254 | C8: 2023-07-07 | D8: Laptop | E8: Electronics | F8: 7 | G8: 843.12 | H8: 5901.84 | I8: Completed | J8: Central | K8: customer0254@example.com
A9: ORD00010 | C9: 2023-07-27 | D9: Keyboard | E9: Accessories | F9: 9 | G9: 0 | H9: 0 | I9: Pending | J9: West
A10: ORD00326 | B10: CUST0125 | C10: 2024-12-16 | D10: headphones | E10: Audio | F10: 3 | G10: 135.6 | H10: 406.8 | I10: Pending | J10: West | K10: customer0125@example.com
A11: ORD00248 | B11: CUST0078 | C11: 2024-09-11 | D11: Laptop | E11: electronics | F11: 1 | G11: 844.29 | H11: 844.29 | I11: Refunded | J11: West | K11: customer0078@example.com
A12: ORD00466 | B12: CUST0087 | C12: 2023-06-30 | D12: Laptop | E12: Electronics | F12: 9 | G12: 879.84 | H12: 7918.56 | I12: Refunded | J12: South | K12: customer0087@example.com
A13: ORD00354 | B13: CUST0061 | C13: 2024-01-04 | D13: Laptop | E13: Electronics | F13: 1 | G13: 823.36 | H13: 1081.01 | I13: Pending | J13: West | K13: customer0061@example.com
A14: ORD00290 | B14: CUST0112 | C14: 2023-10-19 | D14: Webcam | E14: Electronics | F14: 5 | G14: 0 | H14: 0 | I14: Completed | J14: Central | K14: customer0112@example.com
A15: ORD00085 | B15: CUST0086 | C15: 2023-10-16 | D15: Laptop | E15: Electronics | F15: 2 | G15: 962.98 | H15: 1925.96 | I15: Pending | J15: West Region | K15: customer0086@example.com
A16: ORD00011 | C16: 2024-05-18 | D16: Laptop Stand | E16: Accessories | F16: 6 | G16: 52.94 | H16: 317.64 | I16: Refunded | J16: East
A17: ORD00325 | B17: CUST0126 | C17: 2023-06-08 | D17: Keyboard | E17: accessories | F17: 6 | G17: 86.16 | H17: 516.96 | I17: Pending | K17: customer0126@example.com
A18: ORD00079 | B18: CUST0186 | C18: 2024-10-17 | D18: Laptop Stand | E18: accessories | F18: 7 | G18: 50.38 | H18: 352.66 | I18: Pending | J18: North | K18: customer0186@example.com
A19: ORD00031 | B19: CUST0001 | C19: 16/11/2023 | D19: Mouse | F19: 8 | G19: 25.52 | H19: 204.16 | I19: Cancelled | J19: North | K19: customer0001@example.com
A20: ORD00185 | B20: CUST0174 | C20: 2023-06-01 | D20: Keyboard | E20: Accessories | F20: 8 | G20: 76.62 | H20: 612.96 | I20: Cancelled | J20: West | K20: customer0174@example.com
A21: ORD00196 | B21: CUST0074 | C21: 2023-10-01 | D21: Mouse | E21: Accessories | F21: 8 | G21: 25.99 | H21: 207.92 | I21: Cancelled | J21: South | K21: customer0074@example.com
A22: ORD00223 | B22: CUST0257 | C22: 2024-10-17 | D22: Headphones | E22: Audio | F22: 6 | G22: 151.51 | H22: 909.06 | I22: Completed | J22: West | K22: customer0257@example.com
A23: ORD00210 | B23: CUST0045 | C23: 2024-02-06 | D23: Webcam | E23: Electronics | F23: 5 | I23: Refunded | J23: South | K23: customer0045@example.com
A24: ORD00282 | B24: CUST0242 | C24: 2024-08-24 | D24: Laptop Stand | E24: Accessories | F24: 3 | G24: 45.45 | H24: 136.35 | I24: Cancelled | J24: North | K24: customer0242@example.com
A25: ORD00209 | B25: CUST0027 | C25: 2024-03-27 | D25: Laptop Stand | E25: Accessories | F25: 7 | I25: Refunded | J25: Central Region | K25: customer0027@example.com
A26: ORD00125 | B26: CUST0065 | C26: 2024-08-17 | D26: Mouse | F26: 1 | I26: Refunded | J26: South | K26: customer0065@example.com
A27: ORD00251 | B27: CUST0233 | D27: Keyboard | E27: Accessories | F27: 8 | G27: 82.63 | H27: 774.75 | I27: Pending | J27: Central | K27: customer0233example.com
A28: ORD00077 | B28: CUST0288 | C28: 2023-10-15 | D28: Monitor | E28: Electronics | F28: 2 | G28: 281.84 | H28: 563.68 | I28: Refunded | J28: North | K28: customer0288@example.com
A29: ORD00383 | B29: CUST0204 | C29: 2024-04-02 | D29: Webcam | E29: Electronics | F29: 8 | G29: 84.24 | H29: 673.92 | I29: Cancelled | J29: South | K29: customer0204@example.com
A30: ORD00343 | B30: CUST0287 | C30: 2023-10-13 | D30: Monitor | E30: Electronics | F30: 8 | G30: 293.46 | H30: 1384.72 | I30: Completed | J30: south | K30: customer0287@example.com
A31: ORD00324 | B31: CUST0288 | C31: 2023-11-05 | D31: Keyboard | E31: accessories | F31: 5 | G31: 78.24 | H31: 391.2 | I31: Refunded | J31: North | K31: customer0288@example.com
A32: ORD00245 | B32: CUST0043 | C32: 2023-04-05 | D32: Mouse | E32: Accessories | F32: 1 | I32: Pending | J32: Central | K32: customer0043example.com
A33: ORD00332 | B33: CUST0245 | C33: 2024-07-10 | D33: Laptop | E33: Electronics | F33: 8 | G33: 974.13 | H33: 7793.04 | I33: Pending | J33: Central | K33: customer0245@example.com
A34: ORD00141 | B34: CUST0230 | C34: 03-13-2024 | D34: Mouse | E34: Accessories | F34: 7 | G34: 27.88 | H34: 195.16 | I34: Refunded | J34: north | K34: customer0230@example.com
A35: ORD00010 | C35: 2023-07-27 | D35: Keyboard | E35: Accessories | F35: 9 | G35: 0 | H35: 0 | I35: Pending | J35: West
A36: ORD00073 | B36: CUST0116 | C36: 2024-12-03 | D36: Webcam | E36: Electronics | F36: 5 | I36: Cancelled | J36: central | K36: customer0116@example.com
A37: ORD00401 | B37: CUST0264 | D37: Laptop | E37: Electronics | F37: 3 | G37: -899.99 | H37: -2699.97 | I37: Pending | J37: North | K37: 0264@
A38: ORD00488 | B38: CUST0080 | C38: 2023-05-10 | D38: Monitor | E38: Electronics | F38: 2 | G38: 287.94 | H38: 575.88 | I38: Pending | J38: West | K38: customer0080@example.com
A39: ORD00226 | B39: CUST0024 | C39: 2024-05-25 | D39: Mouse | E39: Accessories | F39: 1 | G39: 25.5 | H39: 25.5 | I39: Pending | J39: East | K39: customer0024@example.com
A40: ORD00074 | B40: CUST0164 | C40: 2024-04-09 | D40: Keyboard | E40: Accessories | F40: 2 | G40: 79.34 | H40: 158.68 | I40: Completed | J40: North | K40: customer0164@example.com
...
