Workbook
Name Slicer_Experience_Tiers: #N/A
Name Slicer_type_1: #N/A

Sheet Summary Stats
A1: Pokemon Dataset Summary Statistics
A4: Metric | B4: Value | D4: Category | E4: Value | F4: Pokemon
A5: Total Pokemon | B5: =COUNTA('Clean Data'!A:A)-1 -> 250 | D5: Highest HP | E5: =MAX('Clean Data'!H:H) -> 255 | F5: =INDEX('Clean Data'!B:B, MATCH(MAX('Clean Data'!H:H),'Clean Data'!H:H,0)) -> Blissey
A6: Average Height | B6: =AVERAGE('Clean Data'!C:C) -> 11.844 | D6: Highest Attack | E6: =MAX('Clean Data'!I:I) -> 134 | F6: =INDEX('Clean Data'!B:B, MATCH(MAX('Clean Data'!I:I),'Clean Data'!I:I,0)) -> Dragonite
A7: Average Weight | B7: =AVERAGE('Clean Data'!D:D) -> 473.768 | D7: Highest Defense | E7: =MAX('Clean Data'!J:J) -> 230 | F7: =INDEX('Clean Data'!B:B, MATCH(MAX('Clean Data'!J:J),'Clean Data'!J:J,0)) -> Shuckle
A8: Average Base Experience | B8: =AVERAGE('Clean Data'!E:E) -> 136.244 | D8: Highest Speed | E8: =MAX('Clean Data'!M:M) -> 150 | F8: =INDEX('Clean Data'!B:B, MATCH(MAX('Clean Data'!M:M),'Clean Data'!M:M,0)) -> Electrode
A9: Average HP | B9: =AVERAGE('Clean Data'!H:H) -> 66.776 | D9: Highest Total Stats | E9: =MAX('Clean Data'!N:N) -> 680 | F9: =INDEX('Clean Data'!B:B, MATCH(MAX('Clean Data'!N:N),'Clean Data'!N:N,0)) -> Mewtwo
A10: Average Attack | B10: =AVERAGE('Clean Data'!I:I) -> 70.944 | D10: Heaviest Pokemon | E10: =MAX('Clean Data'!D:D) -> 4600 | F10: =INDEX('Clean Data'!B:B, MATCH(MAX('Clean Data'!D:D),'Clean Data'!D:D,0)) -> Snorlax
A11: Average Defense | B11: =AVERAGE('Clean Data'!J:J) -> 68.684 | D11: Tallest Pokemon | E11: =MAX('Clean Data'!C:C) -> 92 | F11: =INDEX('Clean Data'!B:B, MATCH(MAX('Clean Data'!C:C),'Clean Data'!C:C,0)) -> Steelix
A12: Average Special Attack | B12: =AVERAGE('Clean Data'!K:K) -> 65.952 | D12: Highest Sp.Att | E12: =MAX('Clean Data'!K:K) -> 154 | F12: =INDEX('Clean Data'!B:B, MATCH(MAX('Clean Data'!K:K),'Clean Data'!K:K,0)) -> Mewtwo
A13: Average Special Defense | B13: =AVERAGE('Clean Data'!L:L) -> 68.452 | D13: Highest Sp.Def | E13: =MAX('Clean Data'!L:L) -> 230 | F13: =INDEX('Clean Data'!B:B, MATCH(MAX('Clean Data'!L:L),'Clean Data'!L:L,0)) -> Shuckle
A14: Average Speed | B14: =AVERAGE('Clean Data'!M:M) -> 65.88
A15: Average Total Stats | B15: =AVERAGE('Clean Data'!N:N) -> 406.688

Sheet Dashboard
B2: POKEMON STATS ANALYSIS DASHBOARD GEN 1-2
B4: Interactive Analysis of Pokemon Statistics From Generation 1-2
B6: Total Pokemon | E6: Average Base State Total | H6: Type Diversity | K6: Legendary
B7: =COUNTA('Clean Data'!A:A)-1 -> 250 | E7: =ROUND(AVERAGE('Clean Data'!O2:O251),0) -> 68 | H7: =COUNTA(_xlfn.UNIQUE('Clean Data'!F2:F251)) -> 17 | K7: 14
B9: Across Gen 1-2 | E9: Mean Stat Total | H9: Primary Types | K9: 5.6% Of Total Pokemon
B11: Strongest Pokemon | H11: Fastest Pokemon
B12: =INDEX('Clean Data'!B2:B251,MATCH(MAX('Clean Data'!N2:N251), 'Clean Data'!N2:N251,0)) -> Mewtwo | H12: =INDEX('Clean Data'!B2:B251,MATCH(MAX('Clean Data'!M2:M251),'Clean Data'!M2:M251,0)) -> Electrode
B14: ="BST: " & MAX('Clean Data'!N2:N251) -> BST: 680 | H14: ="Speed: " & MAX('Clean Data'!M2:M251) -> Speed: 150
B16: FILTERS & CONTROLS

Sheet Sheet2
A1: type_1 | B1: (All)
A3: Row Labels | B3: Sum of Total Stats
A4: Articuno | B4: 580 | S4: Row Labels | T4: Average of attack | U4: Average of defense | V4: Average of special_attack | W4: Average of special_defense | X4: Average of speed | Y4: Average of hp
A5: Dragonite | B5: 600 | S5: bug | T5: 66.136364 | U5: 70.681818 | V5: 47.272727 | W5: 68.636364 | X5: 54.545455 | Y5: 55.909091
A6: Entei | B6: 580 | S6: dark | T6: 79 | U6: 57.4 | V6: 74 | W6: 75.4 | X6: 86.2 | Y6: 66
A7: Ho-oh | B7: 680 | S7: dragon | T7: 94 | U7: 68.333333 | V7: 73.333333 | W7: 73.333333 | X7: 66.666667 | Y7: 64.333333
A8: Lugia | B8: 680 | S8: electric | T8: 61.066667 | U8: 59.266667 | V8: 86.333333 | W8: 69.666667 | X8: 87 | Y8: 57.333333
A9: Mew | B9: 600 | S9: fairy | T9: 57.142857 | U9: 60.571429 | V9: 60 | W9: 68.571429 | X9: 35 | Y9: 65
A10: Mewtwo | B10: 680 | S10: fighting | T10: 94.444444 | U10: 61.888889 | V10: 42.777778 | W10: 73.333333 | X10: 63.111111 | Y10: 58.888889
A11: Moltres | B11: 580 | S11: fire | T11: 80.85 | U11: 65.1 | V11: 84.7 | W11: 76.2 | X11: 78.8 | Y11: 65.35
A12: Raikou | B12: 580 | S12: ghost | T12: 52.5 | U12: 48.75 | V12: 107.5 | W12: 62.5 | X12: 92.5 | Y12: 48.75
A13: Suicune | B13: 580 | S13: grass | T13: 64.809524 | U13: 67.619048 | V13: 76.666667 | W13: 69.285714 | X13: 55.238095 | Y13: 62.380952
A14: Tyranitar | B14: 600 | S14: ground | T14: 84.545455 | U14: 88.636364 | V14: 40.909091 | W14: 51.818182 | X14: 58.181818 | Y14: 64.545455
A15: Zapdos | B15: 580 | S15: ice | T15: 61.666667 | U15: 52.5 | V15: 75 | W15: 70 | X15: 70 | Y15: 65.833333
A16: Grand Total | B16: 7320 | S16: normal | T16: 66.540541 | U16: 53.72973 | V16: 54.459459 | W16: 62.405405 | X16: 66.621622 | Y16: 82.135135
S17: poison | T17: 76.133333 | U17: 67.866667 | V17: 58 | W17: 62.866667 | X17: 63.533333 | Y17: 65.866667
A18: Row Labels | B18: Count of name | S18: psychic | T18: 61.857143 | U18: 62.214286 | V18: 94.285714 | W18: 86.071429 | X18: 86.428571 | Y18: 73.214286
A19: bug | B19: 22 | S19: rock | T19: 86.307692 | U19: 102.69231 | V19: 60 | W19: 60.384615 | X19: 54.461538 | Y19: 59.615385
A20: dark | B20: 5 | S20: steel | T20: 82.5 | U20: 170 | V20: 47.5 | W20: 67.5 | X20: 50 | Y20: 70
A21: dragon | B21: 3 | S21: water | T21: 69.413043 | U21: 75.978261 | V21: 66.173913 | W21: 70.108696 | X21: 63.456522 | Y21: 69.826087
A22: electric | B22: 15 | S22: Grand Total | T22: 70.944 | U22: 68.684 | V22: 65.952 | W22: 68.452 | X22: 65.88 | Y22: 66.776
A23: fairy | B23: 7
A24: fighting | B24: 9
A25: fire | B25: 20
A26: ghost | B26: 4
A27: grass | B27: 21
A28: ground | B28: 11
A29: ice | B29: 6
A30: normal | B30: 37
A31: poison | B31: 15
A32: psychic | B32: 14
A33: rock | B33: 13
A34: steel | B34: 2
... A36: Grand Total | B36: 250
A39: Count of name | B39: Column Labels
A40: Row Labels | B40: dark | C40: dragon | D40: electric | E40: fairy | F40: fighting | G40: fire | H40: flying | I40: grass | J40: ground | K40: ice | L40: None | M40: poison | N40: psychic | O40: rock | P40: steel | Q40: water | R40: Grand Total
A41: bug | F41: 1 | H41: 5 | I41: 2 | L41: 4 | M41: 7 | O41: 1 | P41: 2 | R41: 22
A42: dark | G42: 2 | H42: 1 | K42: 1 | L42: 1 | R42: 5
A43: dragon | H43: 1 | L43: 2 | R43: 3
A44: electric | H44: 1 | L44: 12 | P44: 2 | R44: 15
...

Sheet Pivot Analysis
A1: Pivot Table Analysis
A4: Average Stats By Primary Type | J4: Experience Tiers
A6: Row Labels | B6: Average of hp | C6: Average of attack | D6: Average of defense | E6: Average of special_attack | F6: Average of special_defense | G6: Average of speed | H6: Average of Total Stats | J6: Row Labels | K6: Count of name | L6: Average of hp | M6: Average of attack | N6: Average of defense | O6: Average of special_attack | P6: Average of special_defense | Q6: Average of speed | R6: Average of Total Stats
A7: bug | B7: 55.909091 | C7: 66.136364 | D7: 70.681818 | E7: 47.272727 | F7: 68.636364 | G7: 54.545455 | H7: 363.18182 | J7: HIGH | K7: 24 | L7: 79.541667 | M7: 86.208333 | N7: 81.916667 | O7: 90 | P7: 87 | Q7: 82 | R7: 506.66667
A8: dark | B8: 66 | C8: 79 | D8: 57.4 | E8: 74 | F8: 75.4 | G8: 86.2 | H8: 438 | J8: Legendary | K8: 14 | L8: 120.64286 | M8: 90.214286 | N8: 84.285714 | O8: 99.928571 | P8: 109.14286 | Q8: 89.357143 | R8: 593.57143
A9: dragon | B9: 64.333333 | C9: 94 | D9: 68.333333 | E9: 73.333333 | F9: 73.333333 | G9: 66.666667 | H9: 440 | J9: Low | K9: 97 | L9: 48.42268 | M9: 53.329897 | N9: 52.618557 | O9: 48.907216 | P9: 47.278351 | Q9: 53.216495 | R9: 303.7732
A10: electric | B10: 57.333333 | C10: 61.066667 | D10: 59.266667 | E10: 86.333333 | F10: 69.666667 | G10: 87 | H10: 420.66667 | J10: Medium | K10: 115 | L10: 73.034783 | M10: 80.269565 | N10: 77.573913 | O10: 71.173913 | P10: 77.486957 | Q10: 70.33913 | R10: 449.87826
A11: fairy | B11: 65 | C11: 57.142857 | D11: 60.571429 | E11: 60 | F11: 68.571429 | G11: 35 | H11: 346.28571 | J11: Grand Total | K11: 250 | L11: 66.776 | M11: 70.944 | N11: 68.684 | O11: 65.952 | P11: 68.452 | Q11: 65.88 | R11: 406.688
A12: fighting | B12: 58.888889 | C12: 94.444444 | D12: 61.888889 | E12: 42.777778 | F12: 73.333333 | G12: 63.111111 | H12: 394.44444
A13: fire | B13: 65.35 | C13: 80.85 | D13: 65.1 | E13: 84.7 | F13: 76.2 | G13: 78.8 | H13: 451
A14: ghost | B14: 48.75 | C14: 52.5 | D14: 48.75 | E14: 107.5 | F14: 62.5 | G14: 92.5 | H14: 412.5
A15: grass | B15: 62.380952 | C15: 64.809524 | D15: 67.619048 | E15: 76.666667 | F15: 69.285714 | G15: 55.238095 | H15: 396
A16: ground | B16: 64.545455 | C16: 84.545455 | D16: 88.636364 | E16: 40.909091 | F16: 51.818182 | G16: 58.181818 | H16: 388.63636
A17: ice | B17: 65.833333 | C17: 61.666667 | D17: 52.5 | E17: 75 | F17: 70 | G17: 70 | H17: 395
A18: normal | B18: 82.135135 | C18: 66.540541 | D18: 53.72973 | E18: 54.459459 | F18: 62.405405 | G18: 66.621622 | H18: 385.89189
A19: poison | B19: 65.866667 | C19: 76.133333 | D19: 67.866667 | E19: 58 | F19: 62.866667 | G19: 63.533333 | H19: 394.26667
A20: psychic | B20: 73.214286 | C20: 61.857143 | D20: 62.214286 | E20: 94.285714 | F20: 86.071429 | G20: 86.428571 | H20: 464.07143
A21: rock | B21: 59.615385 | C21: 86.307692 | D21: 102.69231 | E21: 60 | F21: 60.384615 | G21: 54.461538 | H21: 423.46154
A22: steel | B22: 70 | C22: 82.5 | D22: 170 | E22: 47.5 | F22: 67.5 | G22: 50 | H22: 487.5
A23: water | B23: 69.826087 | C23: 69.413043 | D23: 75.978261 | E23: 66.173913 | F23: 70.108696 | G23: 63.456522 | H23: 414.95652
A24: Grand Total | B24: 66.776 | C24: 70.944 | D24: 68.684 | E24: 65.952 | F24: 68.452 | G24: 65.88 | H24: 406.688
A27: Pokemon Count By Type | D27: Dual Type Analysis
A29: Row Labels | B29: Count of name | D29: Count of name | E29: Column Labels
A30: water | B30: 46 | D30: Row Labels | E30: dark | F30: dragon | G30: electric | H30: fairy | I30: fighting | J30: fire | K30: flying | L30: grass | M30: ground | N30: ice | O30: None | P30: poison | Q30: psychic | R30: rock | S30: steel | T30: water | U30: Grand Total
A31: normal | B31: 37 | D31: water | F31: 1 | G31: 2 | H31: 2 | I31: 1 | K31: 2 | M31: 2 | N31: 3 | O31: 25 | P31: 3 | Q31: 4 | R31: 1 | U31: 46
A32: bug | B32: 22 | D32: normal | H32: 3 | K32: 10 | O32: 23 | Q32: 1 | U32: 37
A33: grass | B33: 21 | D33: bug | I33: 1 | K33: 5 | L33: 2 | O33: 4 | P33: 7 | R33: 1 | S33: 2 | U33: 22
A34: fire | B34: 20 | D34: grass | K34: 3 | O34: 7 | P34: 9 | Q34: 2 | U34: 21
A35: poison | B35: 15 | D35: fire | K35: 3 | O35: 16 | R35: 1 | U35: 20
A36: electric | B36: 15 | D36: poison | K36: 3 | M36: 2 | O36: 10 | U36: 15
A37: psychic | B37: 14 | D37: electric | K37: 1 | O37: 12 | S37: 2 | U37: 15
A38: rock | B38: 13 | D38: psychic | H38: 1 | K38: 3 | O38: 10 | U38: 14
A39: ground | B39: 11 | D39: rock | E39: 1 | K39: 1 | M39: 6 | O39: 1 | T39: 4 | U39: 13
A40: fighting | B40: 9 | D40: ground | K40: 1 | O40: 8 | R40: 2 | U40: 11
A41: fairy | B41: 7 | D41: fighting | O41: 9 | U41: 9
A42: ice | B42: 6 | D42: fairy | K42: 1 | O42: 6 | U42: 7
A43: dark | B43: 5 | D43: ice | K43: 2 | M43: 2 | Q43: 2 | U43: 6
A44: ghost | B44: 4 | D44: dark | J44: 2 | K44: 1 | N44: 1 | O44: 1 | U44: 5
A45: dragon | B45: 3 | D45: ghost | O45: 1 | P45: 3 | U45: 4
A46: steel | B46: 2 | D46: dragon | K46: 1 | O46: 2 | U46: 3
...

Sheet Charts 
B1: Chart Analysis
B5: Pokemon Count By Type | K5: Duel Type Analysis
B25: Average Stats Per Type | K25: Experience Stats

Sheet Type Effectiveness Insights
A1: Pokemon Type Effectiveness Insights/Statistics
A4: Offensive Statistics Per Type | F4: Defense Statistics Per Type
A6: Row Labels | B6: Average of attack | C6: Average of special_attack | D6: Average of Total Offensive Power | F6: Row Labels | G6: Average of defense | H6: Average of special_defense | I6: Average of Total Defensive Power
A7: bug | B7: 66.136364 | C7: 47.272727 | D7: 113.40909 | F7: bug | G7: 70.681818 | H7: 68.636364 | I7: 139.31818
A8: dark | B8: 79 | C8: 74 | D8: 153 | F8: dark | G8: 57.4 | H8: 75.4 | I8: 132.8
A9: dragon | B9: 94 | C9: 73.333333 | D9: 167.33333 | F9: dragon | G9: 68.333333 | H9: 73.333333 | I9: 141.66667
A10: electric | B10: 61.066667 | C10: 86.333333 | D10: 147.4 | F10: electric | G10: 59.266667 | H10: 69.666667 | I10: 128.93333
A11: fairy | B11: 57.142857 | C11: 60 | D11: 117.14286 | F11: fairy | G11: 60.571429 | H11: 68.571429 | I11: 129.14286
A12: fighting | B12: 94.444444 | C12: 42.777778 | D12: 137.22222 | F12: fighting | G12: 61.888889 | H12: 73.333333 | I12: 135.22222
A13: fire | B13: 80.85 | C13: 84.7 | D13: 165.55 | F13: fire | G13: 65.1 | H13: 76.2 | I13: 141.3
A14: ghost | B14: 52.5 | C14: 107.5 | D14: 160 | F14: ghost | G14: 48.75 | H14: 62.5 | I14: 111.25
A15: grass | B15: 64.809524 | C15: 76.666667 | D15: 141.47619 | F15: grass | G15: 67.619048 | H15: 69.285714 | I15: 136.90476
A16: ground | B16: 84.545455 | C16: 40.909091 | D16: 125.45455 | F16: ground | G16: 88.636364 | H16: 51.818182 | I16: 140.45455
A17: ice | B17: 61.666667 | C17: 75 | D17: 136.66667 | F17: ice | G17: 52.5 | H17: 70 | I17: 122.5
A18: normal | B18: 66.540541 | C18: 54.459459 | D18: 121 | F18: normal | G18: 53.72973 | H18: 62.405405 | I18: 116.13514
... A24: Grand Total | B24: 70.944 | C24: 65.952 | D24: 136.896 | F24: Grand Total | G24: 68.684 | H24: 68.452 | I24: 137.136
A26: Statistics for Speed Per Type | F26: Statistics for BMI Per Type
A28: Row Labels | B28: Average of speed | F28: Row Labels | G28: Average of BMI Metric (Weight/Height Ratio)
A29: bug | B29: 54.545455 | F29: bug | G29: 28.97602
A30: dark | B30: 86.2 | F30: dark | G30: 21.062222
A31: dragon | B31: 66.666667 | F31: dragon | G31: 33.804293
A32: electric | B32: 87 | F32: electric | G32: 34.176256
A33: fairy | B33: 35 | F33: fairy | G33: 15.912611
A34: fighting | B34: 63.111111 | F34: fighting | G34: 41.551984
A35: fire | B35: 78.8 | F35: fire | G35: 39.276484
A36: ghost | B36: 92.5 | F36: ghost | G36: 7.1419986
A37: grass | B37: 55.238095 | F37: grass | G37: 16.490088
A38: ground | B38: 58.181818 | F38: ground | G38: 52.316302
A39: ice | B39: 70 | F39: ice | G39: 26.890548
A40: normal | B40: 66.621622 | F40: normal | G40: 33.75443
... A46: Grand Total | B46: 65.88 | F46: Grand Total | G46: 34.040206
A50: Type Chart
A52: Defending→ | B52: Normal | C52: Fire | D52: Water | E52: Grass | F52: Electric | G52: Ice | H52: Fighting | I52: Poison | J52: Ground | K52: Flying | L52: Psychic | M52: Bug | N52: Rock | O52: Ghost | P52: Dragon | Q52: Dark | R52: Steel | S52: Fairy
A53: Attacking↓
A54: Normal | B54: 1 | C54: 1 | D54: 1 | E54: 1 | F54: 1 | G54: 1 | H54: 1 | I54: 1 | J54: 1 | K54: 1 | L54: 1 | M54: 1 | N54: 0.5 | O54: 0 | P54: 1 | Q54: 1 | R54: 0.5 | S54: 1
A55: Fire | B55: 1 | C55: 0.5 | D55: 0.5 | E55: 2 | F55: 1 | G55: 2 | H55: 1 | I55: 1 | J55: 1 | K55: 1 | L55: 1 | M55: 2 | N55: 0.5 | O55: 1 | P55: 0.5 | Q55: 1 | R55: 2 | S55: 1
A56: Water | B56: 1 | C56: 2 | D56: 0.5 | E56: 0.5 | F56: 1 | G56: 1 | H56: 1 | I56: 1 | J56: 2 | K56: 1 | L56: 1 | M56: 1 | N56: 2 | O56: 1 | P56: 0.5 | Q56: 1 | R56: 1 | S56: 1
A57: Grass | B57: 1 | C57: 0.5 | D57: 2 | E57: 0.5 | F57: 1 | G57: 1 | H57: 1 | I57: 0.5 | J57: 2 | K57: 0.5 | L57: 1 | M57: 0.5 | N57: 2 | O57: 1 | P57: 0.5 | Q57: 1 | R57: 0.5 | S57: 1
A58: Electric | B58: 1 | C58: 1 | D58: 2 | E58: 0.5 | F58: 0.5 | G58: 1 | H58: 1 | I58: 1 | J58: 0 | K58: 2 | L58: 1 | M58: 1 | N58: 1 | O58: 1 | P58: 0.5 | Q58: 1 | R58: 1 | S58: 1
A59: Ice | B59: 1 | C59: 0.5 | D59: 0.5 | E59: 2 | F59: 1 | G59: 0.5 | H59: 1 | I59: 1 | J59: 2 | K59: 2 | L59: 1 | M59: 1 | N59: 1 | O59: 1 | P59: 2 | Q59: 1 | R59: 0.5 | S59: 1
...

Sheet Correlation Analysis
A1: Correlation Analysis
B5: hp | C5: attack | D5: defense | E5: special_attack | F5: special_defense | G5: speed
A6: hp | B6: 1 | C6: =CORREL('Clean Data'!$H$2:$H$251,'Clean Data'!$I$2:$I$251) -> 0.24214005 | D6: =CORREL('Clean Data'!$H$2:$H$251,'Clean Data'!$J$2:$J$251) -> 0.11852374 | E6: =CORREL('Clean Data'!$H$2:$H$251,'Clean Data'!$K$2:$K$251) -> 0.25170132 | F6: =CORREL('Clean Data'!$H$2:$H$251,'Clean Data'!$L$2:$L$251) -> 0.4224905 | G6: =CORREL('Clean Data'!$H$2:$H$251,'Clean Data'!$M$2:$M$251) -> 0.020284911
A7: attack | B7: =CORREL('Clean Data'!$H$2:$H$251,'Clean Data'!$I$2:$I$251) -> 0.24214005 | C7: 1 | D7: =CORREL('Clean Data'!$I$2:$I$251,'Clean Data'!$J$2:$J$251) -> 0.4407508 | E7: =CORREL('Clean Data'!$I$2:$I$251,'Clean Data'!$K$2:$K$251) -> 0.23562393 | F7: =CORREL('Clean Data'!$I$2:$I$251,'Clean Data'!$L$2:$L$251) -> 0.23949516 | G7: =CORREL('Clean Data'!$I$2:$I$251,'Clean Data'!$M2:$M$251) -> 0.27357637
A8: defense | B8: 0.11852374 | C8: 0.4407508 | D8: 1 | E8: =CORREL('Clean Data'!$J$2:$J$251,'Clean Data'!$K$2:$K$251) -> 0.13256289 | F8: =CORREL('Clean Data'!$J$2:$J$251,'Clean Data'!$L$2:$L$251) -> 0.36689934 | G8: =CORREL('Clean Data'!$J$2:$J$251,'Clean Data'!$M$2:$M$251) -> -0.037476073
A9: special_attack | B9: 0.25170132 | C9: 0.23562393 | D9: 0.13256289 | E9: 1 | F9: =CORREL('Clean Data'!$K$2:$K$251,'Clean Data'!$L$2:$L$251) -> 0.4340213 | G9: =CORREL('Clean Data'!$K$2:$K$251,'Clean Data'!$M$2:$M$251) -> 0.40917845
A10: special_defense | B10: 0.4224905 | C10: 0.23949516 | D10: 0.36689934 | E10: 0.4340213 | F10: 1 | G10: =CORREL('Clean Data'!$L$2:$L$251,'Clean Data'!$M$2:$M$251) -> 0.28858411
A11: speed | B11: 0.020284911 | C11: 0.27357637 | D11: -0.037476073 | E11: 0.40917845 | F11: 0.28858411 | G11: 1
A13: Stat Pair | B13: Correlation | C13: Strength | D13: Interpretation
A14: HP <-> Special Defense | B14: =INDEX($B$6:$G$11,1,5) -> 0.4224905 | C14: Moderate Positive | D14: Tanky Pokemon have high special defense - defense arechetype
A15: Attack <-> Defense | B15: =INDEX($B$6:$G$11,2,3) -> 0.4407508 | C15: Moderative Positive | D15: Physical stats correlate
A16: Defense <-> Special Defense | B16: =INDEX($B$6:$G$11,3,5) -> 0.36689934 | C16: Positive | D16: Defensive stats cluster together
A17: Special Attack <-> Special Defense | B17: =INDEX($B$6:$G$11,4,5) -> 0.4340213 | C17: Moderate Positive | D17: Special stats are linked
A18: Special Attack -> Speed | B18: =INDEX($B$6:$G$11,4,6) -> 0.40917845 | C18: Moderative Positive | D18: Fast Pokemon tend to have high special attack
A19: Speed <-> Defense | B19: =INDEX($B$6:$G$11,6,3) -> -0.037476073 | C19: Weak Negative | D19: Glass Cannon Effect - fast Pokemon sacrifice defense
A20: HP <-> Speed | B20: =INDEX($B$6:$G$11,1,6) -> 0.020284911 | C20: None | D20: No relationship - can have fast tanks or slow tanks

Sheet Top Performers
A1: Top Performing Pokemon
A4: Top 10 by Total Stats
A6: pokedex_id | B6: name | C6: height | D6: weight | E6: base_experience | F6: type_1 | G6: type_2 | H6: hp | I6: attack | J6: defense | K6: special_attack | L6: special_defense | M6: speed | N6: Total Stats | O6: Average Stats | P6: BMI Metric (Weight/Height Ratio) | Q6: Type Count | R6: Experience Tiers
A7: 150 | B7: Mewtwo | C7: 20 | D7: 1220 | E7: 306 | F7: psychic | G7: None | H7: 106 | I7: 110 | J7: 90 | K7: 154 | L7: 90 | M7: 130 | N7: =SUM(H7:M7) -> 680 | O7: =AVERAGE(H7:M7) -> 113.33333 | P7: =D7/C7 -> 61 | Q7: =IF(G7="None", 1,2) -> 1 | R7: =IF(E7<100,"Low",IF(E7<200,"Medium",IF(E7<250,"HIGH",IF(E7>250,"Legendary")))) -> Legendary
A8: 249 | B8: Lugia | C8: 52 | D8: 2160 | E8: 306 | F8: psychic | G8: flying | H8: 106 | I8: 90 | J8: 130 | K8: 90 | L8: 154 | M8: 110 | N8: =SUM(H8:M8) -> 680 | O8: =AVERAGE(H8:M8) -> 113.33333 | P8: =D8/C8 -> 41.538462 | Q8: =IF(G8="None", 1,2) -> 2 | R8: =IF(E8<100,"Low",IF(E8<200,"Medium",IF(E8<250,"HIGH",IF(E8>250,"Legendary")))) -> Legendary
A9: 250 | B9: Ho-oh | C9: 38 | D9: 1990 | E9: 306 | F9: fire | G9: flying | H9: 106 | I9: 130 | J9: 90 | K9: 110 | L9: 154 | M9: 90 | N9: =SUM(H9:M9) -> 680 | O9: =AVERAGE(H9:M9) -> 113.33333 | P9: =D9/C9 -> 52.368421 | Q9: =IF(G9="None", 1,2) -> 2 | R9: =IF(E9<100,"Low",IF(E9<200,"Medium",IF(E9<250,"HIGH",IF(E9>250,"Legendary")))) -> Legendary
A10: 149 | B10: Dragonite | C10: 22 | D10: 2100 | E10: 270 | F10: dragon | G10: flying | H10: 91 | I10: 134 | J10: 95 | K10: 100 | L10: 100 | M10: 80 | N10: =SUM(H10:M10) -> 600 | O10: =AVERAGE(H10:M10) -> 100 | P10: =D10/C10 -> 95.454545 | Q10: =IF(G10="None", 1,2) -> 2 | R10: =IF(E10<100,"Low",IF(E10<200,"Medium",IF(E10<250,"HIGH",IF(E10>250,"Legendary")))) -> Legendary
A11: 151 | B11: Mew | C11: 4 | D11: 40 | E11: 270 | F11: psychic | G11: None | H11: 100 | I11: 100 | J11: 100 | K11: 100 | L11: 100 | M11: 100 | N11: =SUM(H11:M11) -> 600 | O11: =AVERAGE(H11:M11) -> 100 | P11: =D11/C11 -> 10 | Q11: =IF(G11="None", 1,2) -> 1 | R11: =IF(E11<100,"Low",IF(E11<200,"Medium",IF(E11<250,"HIGH",IF(E11>250,"Legendary")))) -> Legendary
A12: 248 | B12: Tyranitar | C12: 20 | D12: 2020 | E12: 270 | F12: rock | G12: dark | H12: 100 | I12: 134 | J12: 110 | K12: 95 | L12: 100 | M12: 61 | N12: =SUM(H12:M12) -> 600 | O12: =AVERAGE(H12:M12) -> 100 | P12: =D12/C12 -> 101 | Q12: =IF(G12="None", 1,2) -> 2 | R12: =IF(E12<100,"Low",IF(E12<200,"Medium",IF(E12<250,"HIGH",IF(E12>250,"Legendary")))) -> Legendary
A13: 144 | B13: Articuno | C13: 17 | D13: 554 | E13: 261 | F13: ice | G13: flying | H13: 90 | I13: 85 | J13: 100 | K13: 95 | L13: 125 | M13: 85 | N13: =SUM(H13:M13) -> 580 | O13: =AVERAGE(H13:M13) -> 96.666667 | P13: =D13/C13 -> 32.588235 | Q13: =IF(G13="None", 1,2) -> 2 | R13: =IF(E13<100,"Low",IF(E13<200,"Medium",IF(E13<250,"HIGH",IF(E13>250,"Legendary")))) -> Legendary
A14: 145 | B14: Zapdos | C14: 16 | D14: 526 | E14: 261 | F14: electric | G14: flying | H14: 90 | I14: 90 | J14: 85 | K14: 125 | L14: 90 | M14: 100 | N14: =SUM(H14:M14) -> 580 | O14: =AVERAGE(H14:M14) -> 96.666667 | P14: =D14/C14 -> 32.875 | Q14: =IF(G14="None", 1,2) -> 2 | R14: =IF(E14<100,"Low",IF(E14<200,"Medium",IF(E14<250,"HIGH",IF(E14>250,"Legendary")))) -> Legendary
A15: 146 | B15: Moltres | C15: 20 | D15: 600 | E15: 261 | F15: fire | G15: flying | H15: 90 | I15: 100 | J15: 90 | K15: 125 | L15: 85 | M15: 90 | N15: =SUM(H15:M15) -> 580 | O15: =AVERAGE(H15:M15) -> 96.666667 | P15: =D15/C15 -> 30 | Q15: =IF(G15="None", 1,2) -> 2 | R15: =IF(E15<100,"Low",IF(E15<200,"Medium",IF(E15<250,"HIGH",IF(E15>250,"Legendary")))) -> Legendary
A17: Top 10 By Each Stat
A20: Top 10 By HP | D20: Top 10 By Attack | G20: Top 10 By Defense | J20: Top 10 By Special Attack | M20: Top 10 By Special Defense | P20: Top 10 By Speed
A22: Row Labels | B22: Sum of hp | D22: Row Labels | E22: Sum of attack | G22: Row Labels | H22: Sum of defense | J22: Row Labels | K22: Sum of special_attack | M22: Row Labels | N22: Sum of special_defense | P22: Row Labels | Q22: Sum of speed
A23: Blissey | B23: 255 | D23: Tyranitar | E23: 134 | G23: Shuckle | H23: 230 | J23: Mewtwo | K23: 154 | M23: Shuckle | N23: 230 | P23: Electrode | Q23: 150
A24: Chansey | B24: 250 | D24: Dragonite | E24: 134 | G24: Steelix | H24: 200 | J24: Alakazam | K24: 135 | M24: Lugia | N24: 154 | P24: Aerodactyl | Q24: 130
A25: Wobbuffet | B25: 190 | D25: Rhydon | E25: 130 | G25: Cloyster | H25: 180 | J25: Espeon | K25: 130 | M25: Ho-oh | N25: 154 | P25: Mewtwo | Q25: 130
A26: Snorlax | B26: 160 | D26: Flareon | E26: 130 | G26: Onix | H26: 160 | J26: Gengar | K26: 130 | M26: Mantine | N26: 140 | P26: Crobat | Q26: 130
A27: Wigglytuff | B27: 140 | D27: Scizor | E27: 130 | G27: Forretress | H27: 140 | J27: Moltres | K27: 125 | M27: Blissey | N27: 135 | P27: Jolteon | Q27: 130
A28: Vaporeon | B28: 130 | D28: Ursaring | E28: 130 | G28: Skarmory | H28: 140 | J28: Exeggutor | K28: 125 | M28: Umbreon | N28: 130 | P28: Alakazam | Q28: 120
A29: Lapras | B29: 130 | D29: Ho-oh | E29: 130 | G29: Golem | H29: 130 | J29: Zapdos | K29: 125 | M29: Articuno | N29: 125 | P29: Dugtrio | Q29: 120
A30: Lanturn | B30: 125 | D30: Machamp | E30: 130 | G30: Lugia | H30: 130 | J30: Magneton | K30: 120 | M30: Tentacruel | N30: 120 | P30: Starmie | Q30: 115
A31: Jigglypuff | B31: 115 | D31: Kingler | E31: 130 | G31: Omastar | H31: 125 | J31: Kadabra | K31: 120 | M31: Mr-mime | N31: 120 | P31: Sneasel | Q31: 115
A32: Entei | B32: 115 | D32: Gyarados | E32: 125 | G32: Weezing | H32: 120 | J32: Raikou | K32: 115 | M32: Suicune | N32: 115 | P32: Raikou | Q32: 115
A33: Grand Total | B33: 1610 | D33: Heracross | E33: 125 | G33: Rhydon | H33: 120 | J33: Omastar | K33: 115 | M33: Hypno | N33: 115 | P33: Persian | Q33: 115
D34: Pinsir | E34: 125 | G34: Donphan | H34: 120 | J34: Ampharos | K34: 115 | M34: Grand Total | N34: 1538 | P34: Grand Total | Q34: 1370
D35: Grand Total | E35: 1553 | G35: Magcargo | H35: 120 | J35: Haunter | K35: 115
G36: Grand Total | H36: 1915 | J36: Jynx | K36: 115
J37: Grand Total | K37: 1739

Sheet Clean Data
A1: pokedex_id | B1: name | C1: height | D1: weight | E1: base_experience | F1: type_1 | G1: type_2 | H1: hp | I1: attack | J1: defense | K1: special_attack | L1: special_defense | M1: speed | N1: Total Stats | O1: Average Stats | P1: BMI Metric (Weight/Height Ratio) | Q1: Type Count | R1: Experience Tiers | S1: Total Offensive Power | T1: Total Defensive Power | U1: Generation
A2: 1 | B2: Bulbasaur | C2: 7 | D2: 69 | E2: 64 | F2: grass | G2: poison | H2: 45 | I2: 49 | J2: 49 | K2: 65 | L2: 65 | M2: 45 | N2: =SUM(H2:M2) -> 318 | O2: =AVERAGE(H2:M2) -> 53 | P2: =D2/C2 -> 9.8571429 | Q2: =IF(G2="None", 1,2) -> 2 | R2: =IF(E2<100,"Low",IF(E2<200,"Medium",IF(E2<250,"HIGH",IF(E2>250,"Legendary")))) -> Low | S2: =I2+K2 -> 114 | T2: =J2+L2 -> 114 | U2: =IF(A3 <= 151, "Gen 1", IF(A3 > 151, "Gen 2")) -> Gen 1
A3: 2 | B3: Ivysaur | C3: 10 | D3: 130 | E3: 142 | F3: grass | G3: poison | H3: 60 | I3: 62 | J3: 63 | K3: 80 | L3: 80 | M3: 60 | N3: =SUM(H3:M3) -> 405 | O3: =AVERAGE(H3:M3) -> 67.5 | P3: =D3/C3 -> 13 | Q3: =IF(G3="None", 1,2) -> 2 | R3: =IF(E3<100,"Low",IF(E3<200,"Medium",IF(E3<250,"HIGH",IF(E3>250,"Legendary")))) -> Medium | S3: =I3+K3 -> 142 | T3: =J3+L3 -> 143 | U3: =IF(A4 <= 151, "Gen 1", IF(A4 > 151, "Gen 2")) -> Gen 1
A4: 3 | B4: Venusaur | C4: 20 | D4: 1000 | E4: 236 | F4: grass | G4: poison | H4: 80 | I4: 82 | J4: 83 | K4: 100 | L4: 100 | M4: 80 | N4: =SUM(H4:M4) -> 525 | O4: =AVERAGE(H4:M4) -> 87.5 | P4: =D4/C4 -> 50 | Q4: =IF(G4="None", 1,2) -> 2 | R4: =IF(E4<100,"Low",IF(E4<200,"Medium",IF(E4<250,"HIGH",IF(E4>250,"Legendary")))) -> HIGH | S4: =I4+K4 -> 182 | T4: =J4+L4 -> 183 | U4: =IF(A5 <= 151, "Gen 1", IF(A5 > 151, "Gen 2")) -> Gen 1
A5: 4 | B5: Charmander | C5: 6 | D5: 85 | E5: 62 | F5: fire | G5: None | H5: 39 | I5: 52 | J5: 43 | K5: 60 | L5: 50 | M5: 65 | N5: =SUM(H5:M5) -> 309 | O5: =AVERAGE(H5:M5) -> 51.5 | P5: =D5/C5 -> 14.166667 | Q5: =IF(G5="None", 1,2) -> 1 | R5: =IF(E5<100,"Low",IF(E5<200,"Medium",IF(E5<250,"HIGH",IF(E5>250,"Legendary")))) -> Low | S5: =I5+K5 -> 112 | T5: =J5+L5 -> 93 | U5: =IF(A6 <= 151, "Gen 1", IF(A6 > 151, "Gen 2")) -> Gen 1
A6: 5 | B6: Charmeleon | C6: 11 | D6: 190 | E6: 142 | F6: fire | G6: None | H6: 58 | I6: 64 | J6: 58 | K6: 80 | L6: 65 | M6: 80 | N6: =SUM(H6:M6) -> 405 | O6: =AVERAGE(H6:M6) -> 67.5 | P6: =D6/C6 -> 17.272727 | Q6: =IF(G6="None", 1,2) -> 1 | R6: =IF(E6<100,"Low",IF(E6<200,"Medium",IF(E6<250,"HIGH",IF(E6>250,"Legendary")))) -> Medium | S6: =I6+K6 -> 144 | T6: =J6+L6 -> 123 | U6: =IF(A7 <= 151, "Gen 1", IF(A7 > 151, "Gen 2")) -> Gen 1
A7: 6 | B7: Charizard | C7: 17 | D7: 905 | E7: 240 | F7: fire | G7: flying | H7: 78 | I7: 84 | J7: 78 | K7: 109 | L7: 85 | M7: 100 | N7: =SUM(H7:M7) -> 534 | O7: =AVERAGE(H7:M7) -> 89 | P7: =D7/C7 -> 53.235294 | Q7: =IF(G7="None", 1,2) -> 2 | R7: =IF(E7<100,"Low",IF(E7<200,"Medium",IF(E7<250,"HIGH",IF(E7>250,"Legendary")))) -> HIGH | S7: =I7+K7 -> 193 | T7: =J7+L7 -> 163 | U7: =IF(A8 <= 151, "Gen 1", IF(A8 > 151, "Gen 2")) -> Gen 1
A8: 7 | B8: Squirtle | C8: 5 | D8: 90 | E8: 63 | F8: water | G8: None | H8: 44 | I8: 48 | J8: 65 | K8: 50 | L8: 64 | M8: 43 | N8: =SUM(H8:M8) -> 314 | O8: =AVERAGE(H8:M8) -> 52.333333 | P8: =D8/C8 -> 18 | Q8: =IF(G8="None", 1,2) -> 1 | R8: =IF(E8<100,"Low",IF(E8<200,"Medium",IF(E8<250,"HIGH",IF(E8>250,"Legendary")))) -> Low | S8: =I8+K8 -> 98 | T8: =J8+L8 -> 129 | U8: =IF(A9 <= 151, "Gen 1", IF(A9 > 151, "Gen 2")) -> Gen 1
A9: 8 | B9: Wartortle | C9: 10 | D9: 225 | E9: 142 | F9: water | G9: None | H9: 59 | I9: 63 | J9: 80 | K9: 65 | L9: 80 | M9: 58 | N9: =SUM(H9:M9) -> 405 | O9: =AVERAGE(H9:M9) -> 67.5 | P9: =D9/C9 -> 22.5 | Q9: =IF(G9="None", 1,2) -> 1 | R9: =IF(E9<100,"Low",IF(E9<200,"Medium",IF(E9<250,"HIGH",IF(E9>250,"Legendary")))) -> Medium | S9: =I9+K9 -> 128 | T9: =J9+L9 -> 160 | U9: =IF(A10 <= 151, "Gen 1", IF(A10 > 151, "Gen 2")) -> Gen 1
A10: 9 | B10: Blastoise | C10: 16 | D10: 855 | E10: 239 | F10: water | G10: None | H10: 79 | I10: 83 | J10: 100 | K10: 85 | L10: 105 | M10: 78 | N10: =SUM(H10:M10) -> 530 | O10: =AVERAGE(H10:M10) -> 88.333333 | P10: =D10/C10 -> 53.4375 | Q10: =IF(G10="None", 1,2) -> 1 | R10: =IF(E10<100,"Low",IF(E10<200,"Medium",IF(E10<250,"HIGH",IF(E10>250,"Legendary")))) -> HIGH | S10: =I10+K10 -> 168 | T10: =J10+L10 -> 205 | U10: =IF(A11 <= 151, "Gen 1", IF(A11 > 151, "Gen 2")) -> Gen 1
A11: 10 | B11: Caterpie | C11: 3 | D11: 29 | E11: 39 | F11: bug | G11: None | H11: 45 | I11: 30 | J11: 35 | K11: 20 | L11: 20 | M11: 45 | N11: =SUM(H11:M11) -> 195 | O11: =AVERAGE(H11:M11) -> 32.5 | P11: =D11/C11 -> 9.6666667 | Q11: =IF(G11="None", 1,2) -> 1 | R11: =IF(E11<100,"Low",IF(E11<200,"Medium",IF(E11<250,"HIGH",IF(E11>250,"Legendary")))) -> Low | S11: =I11+K11 -> 50 | T11: =J11+L11 -> 55 | U11: =IF(A12 <= 151, "Gen 1", IF(A12 > 151, "Gen 2")) -> Gen 1
A12: 11 | B12: Metapod | C12: 7 | D12: 99 | E12: 72 | F12: bug | G12: None | H12: 50 | I12: 20 | J12: 55 | K12: 25 | L12: 25 | M12: 30 | N12: =SUM(H12:M12) -> 205 | O12: =AVERAGE(H12:M12) -> 34.166667 | P12: =D12/C12 -> 14.142857 | Q12: =IF(G12="None", 1,2) -> 1 | R12: =IF(E12<100,"Low",IF(E12<200,"Medium",IF(E12<250,"HIGH",IF(E12>250,"Legendary")))) -> Low | S12: =I12+K12 -> 45 | T12: =J12+L12 -> 80 | U12: =IF(A13 <= 151, "Gen 1", IF(A13 > 151, "Gen 2")) -> Gen 1
A13: 12 | B13: Butterfree | C13: 11 | D13: 320 | E13: 178 | F13: bug | G13: flying | H13: 60 | I13: 45 | J13: 50 | K13: 90 | L13: 80 | M13: 70 | N13: =SUM(H13:M13) -> 395 | O13: =AVERAGE(H13:M13) -> 65.833333 | P13: =D13/C13 -> 29.090909 | Q13: =IF(G13="None", 1,2) -> 2 | R13: =IF(E13<100,"Low",IF(E13<200,"Medium",IF(E13<250,"HIGH",IF(E13>250,"Legendary")))) -> Medium | S13: =I13+K13 -> 135 | T13: =J13+L13 -> 130 | U13: =IF(A14 <= 151, "Gen 1", IF(A14 > 151, "Gen 2")) -> Gen 1
... A250: 249 | B250: Lugia | C250: 52 | D250: 2160 | E250: 306 | F250: psychic | G250: flying | H250: 106 | I250: 90 | J250: 130 | K250: 90 | L250: 154 | M250: 110 | N250: =SUM(H250:M250) -> 680 | O250: =AVERAGE(H250:M250) -> 113.33333 | P250: =D250/C250 -> 41.538462 | Q250: =IF(G250="None", 1,2) -> 2 | R250: =IF(E250<100,"Low",IF(E250<200,"Medium",IF(E250<250,"HIGH",IF(E250>250,"Legendary")))) -> Legendary | S250: =I250+K250 -> 180 | T250: =J250+L250 -> 284 | U250: =IF(A251 <= 151, "Gen 1", IF(A251 > 151, "Gen 2")) -> Gen 2
A251: 250 | B251: Ho-oh | C251: 38 | D251: 1990 | E251: 306 | F251: fire | G251: flying | H251: 106 | I251: 130 | J251: 90 | K251: 110 | L251: 154 | M251: 90 | N251: =SUM(H251:M251) -> 680 | O251: =AVERAGE(H251:M251) -> 113.33333 | P251: =D251/C251 -> 52.368421 | Q251: =IF(G251="None", 1,2) -> 2 | R251: =IF(E251<100,"Low",IF(E251<200,"Medium",IF(E251<250,"HIGH",IF(E251>250,"Legendary")))) -> Legendary | S251: =I251+K251 -> 240 | T251: =J251+L251 -> 244 | U251: Gen 2

Sheet pokemon_stats_2025
A1: pokedex_id | B1: name | C1: height | D1: weight | E1: base_experience | F1: type_1 | G1: type_2 | H1: hp | I1: attack | J1: defense | K1: special_attack | L1: special_defense | M1: speed
A2: 1 | B2: Bulbasaur | C2: 7 | D2: 69 | E2: 64 | F2: grass | G2: poison | H2: 45 | I2: 49 | J2: 49 | K2: 65 | L2: 65 | M2: 45
A3: 2 | B3: Ivysaur | C3: 10 | D3: 130 | E3: 142 | F3: grass | G3: poison | H3: 60 | I3: 62 | J3: 63 | K3: 80 | L3: 80 | M3: 60
A4: 3 | B4: Venusaur | C4: 20 | D4: 1000 | E4: 236 | F4: grass | G4: poison | H4: 80 | I4: 82 | J4: 83 | K4: 100 | L4: 100 | M4: 80
A5: 4 | B5: Charmander | C5: 6 | D5: 85 | E5: 62 | F5: fire | G5: None | H5: 39 | I5: 52 | J5: 43 | K5: 60 | L5: 50 | M5: 65
A6: 5 | B6: Charmeleon | C6: 11 | D6: 190 | E6: 142 | F6: fire | G6: None | H6: 58 | I6: 64 | J6: 58 | K6: 80 | L6: 65 | M6: 80
A7: 6 | B7: Charizard | C7: 17 | D7: 905 | E7: 240 | F7: fire | G7: flying | H7: 78 | I7: 84 | J7: 78 | K7: 109 | L7: 85 | M7: 100
A8: 7 | B8: Squirtle | C8: 5 | D8: 90 | E8: 63 | F8: water | G8: None | H8: 44 | I8: 48 | J8: 65 | K8: 50 | L8: 64 | M8: 43
A9: 8 | B9: Wartortle | C9: 10 | D9: 225 | E9: 142 | F9: water | G9: None | H9: 59 | I9: 63 | J9: 80 | K9: 65 | L9: 80 | M9: 58
A10: 9 | B10: Blastoise | C10: 16 | D10: 855 | E10: 239 | F10: water | G10: None | H10: 79 | I10: 83 | J10: 100 | K10: 85 | L10: 105 | M10: 78
A11: 10 | B11: Caterpie | C11: 3 | D11: 29 | E11: 39 | F11: bug | G11: None | H11: 45 | I11: 30 | J11: 35 | K11: 20 | L11: 20 | M11: 45
A12: 11 | B12: Metapod | C12: 7 | D12: 99 | E12: 72 | F12: bug | G12: None | H12: 50 | I12: 20 | J12: 55 | K12: 25 | L12: 25 | M12: 30
A13: 12 | B13: Butterfree | C13: 11 | D13: 320 | E13: 178 | F13: bug | G13: flying | H13: 60 | I13: 45 | J13: 50 | K13: 90 | L13: 80 | M13: 70
... A251: 250 | B251: Ho-oh | C251: 38 | D251: 1990 | E251: 306 | F251: fire | G251: flying | H251: 106 | I251: 130 | J251: 90 | K251: 110 | L251: 154 | M251: 90
